<?xml version="1.0"?>
<robot xmlns:xacro="http://www.ros.org/wiki/xacro">

	<joint name="HeadYaw" type="revolute">
		<parent link="base_link"/>
		<child link="LowerHead"/>
		<!-- <origin xyz="-0.00661 -0.014699 0.16054" rpy="0 0 0"/> -->
		<origin xyz="0.0035 0 0.1115" rpy="0 0 0"/>
		<axis xyz="0 0 1"/>
		<limit lower="-1.22173048" upper="1.22173048" effort="2.5" velocity="5.759586525"/>
	</joint>
	<link name="LowerHead">
		<xacro:visuals_collisions_lower_head/>
	</link>
	<joint name="HeadPitch" type="revolute">
		<parent link="LowerHead"/>
		<child link="UpperHeadBase"/>
		<origin xyz="-0.01 0 0.049" rpy="0 0 0"/>
		<axis xyz="0 1 0"/>
		<limit upper="0.4" lower="-0.25" effort="2.5" velocity="5.759586525"/>
	</joint>
	<link name="UpperHeadBase">
		<xacro:visuals_collisions_upper_head_base/>
	</link>
	<joint name="HeadPitchDummy" type="continuous">
		<parent link="UpperHeadBase"/>
		<child link="UpperHeadMotor"/>
		<origin xyz="-0.00225 0 0.046" rpy="0 0 0"/>
		<axis xyz="0 1 0"/>
		<mimic joint="HeadPitch" multiplier="-1.0"/>
	</joint>
	<link name="UpperHeadMotor">
		<xacro:visuals_collisions_upper_head_motor/>
	</link>
	<joint name="HeadPitchDummy2" type="continuous">
		<parent link="LowerHead"/>
		<child link="UpperHeadBack"/>
		<!-- <origin xyz="-0.04 0 -0.074" rpy="0 0 0"/> -->
		<origin xyz="-0.0525 0 0.021" rpy="0 0 0"/>
		<axis xyz="0 1 0"/>
		<mimic joint="HeadPitch" multiplier="0.65"/>
	</joint>
	<link name="UpperHeadBack">
		<xacro:visuals_collisions_upper_head_back/>
	</link>

</robot>