<?xml version="1.0" ?>
<!-- =================================================================================== -->
<!-- |    This document was autogenerated by xacro from /home/costas/Workspaces/ros_indigo/jack_ws/src/hros5/hros5_description/urdf/hros5.xacro | -->
<!-- |    EDITING THIS FILE BY HAND IS NOT RECOMMENDED                                 | -->
<!-- =================================================================================== -->
<robot name="hros5" xmlns:xacro="http://www.ros.org/wiki/xacro">
  <transmission name="HeadYaw_Transmission">
    <type>transmission_interface/SimpleTransmission</type>
    <joint name="HeadYaw">
      <hardwareInterface>EffortJointInterface</hardwareInterface>
    </joint>
    <actuator name="HeadYaw_Motor">
      <hardwareInterface>EffortJointInterface</hardwareInterface>
      <mechanicalReduction>1</mechanicalReduction>
    </actuator>
  </transmission>
  <transmission name="HeadPitch_Transmission">
    <type>transmission_interface/SimpleTransmission</type>
    <joint name="HeadPitch">
      <hardwareInterface>EffortJointInterface</hardwareInterface>
    </joint>
    <actuator name="HeadPitch_Motor">
      <hardwareInterface>EffortJointInterface</hardwareInterface>
      <mechanicalReduction>1</mechanicalReduction>
    </actuator>
  </transmission>
  <transmission name="LShoulderPitch_Transmission">
    <type>transmission_interface/SimpleTransmission</type>
    <joint name="LShoulderPitch">
      <hardwareInterface>EffortJointInterface</hardwareInterface>
    </joint>
    <actuator name="LShoulderPitch_Motor">
      <hardwareInterface>EffortJointInterface</hardwareInterface>
      <mechanicalReduction>1</mechanicalReduction>
    </actuator>
  </transmission>
  <transmission name="LShoulderRoll_Transmission">
    <type>transmission_interface/SimpleTransmission</type>
    <joint name="LShoulderRoll">
      <hardwareInterface>EffortJointInterface</hardwareInterface>
    </joint>
    <actuator name="LShoulderRoll_Motor">
      <hardwareInterface>EffortJointInterface</hardwareInterface>
      <mechanicalReduction>1</mechanicalReduction>
    </actuator>
  </transmission>
  <transmission name="LElbowPitch_Transmission">
    <type>transmission_interface/SimpleTransmission</type>
    <joint name="LElbowPitch">
      <hardwareInterface>EffortJointInterface</hardwareInterface>
    </joint>
    <actuator name="LElbowPitch_Motor">
      <hardwareInterface>EffortJointInterface</hardwareInterface>
      <mechanicalReduction>1</mechanicalReduction>
    </actuator>
  </transmission>
  <transmission name="RShoulderPitch_Transmission">
    <type>transmission_interface/SimpleTransmission</type>
    <joint name="RShoulderPitch">
      <hardwareInterface>EffortJointInterface</hardwareInterface>
    </joint>
    <actuator name="RShoulderPitch_Motor">
      <hardwareInterface>EffortJointInterface</hardwareInterface>
      <mechanicalReduction>1</mechanicalReduction>
    </actuator>
  </transmission>
  <transmission name="RShoulderRoll_Transmission">
    <type>transmission_interface/SimpleTransmission</type>
    <joint name="RShoulderRoll">
      <hardwareInterface>EffortJointInterface</hardwareInterface>
    </joint>
    <actuator name="RShoulderRoll_Motor">
      <hardwareInterface>EffortJointInterface</hardwareInterface>
      <mechanicalReduction>1</mechanicalReduction>
    </actuator>
  </transmission>
  <transmission name="RElbowPitch_Transmission">
    <type>transmission_interface/SimpleTransmission</type>
    <joint name="RElbowPitch">
      <hardwareInterface>EffortJointInterface</hardwareInterface>
    </joint>
    <actuator name="RElbowPitch_Motor">
      <hardwareInterface>EffortJointInterface</hardwareInterface>
      <mechanicalReduction>1</mechanicalReduction>
    </actuator>
  </transmission>
  <transmission name="LHipYaw_Transmission">
    <type>transmission_interface/SimpleTransmission</type>
    <joint name="LHipYaw">
      <hardwareInterface>EffortJointInterface</hardwareInterface>
    </joint>
    <actuator name="LHipYaw_Motor">
      <hardwareInterface>EffortJointInterface</hardwareInterface>
      <mechanicalReduction>1</mechanicalReduction>
    </actuator>
  </transmission>
  <transmission name="LHipRoll_Transmission">
    <type>transmission_interface/SimpleTransmission</type>
    <joint name="LHipRoll">
      <hardwareInterface>EffortJointInterface</hardwareInterface>
    </joint>
    <actuator name="LHipRoll_Motor">
      <hardwareInterface>EffortJointInterface</hardwareInterface>
      <mechanicalReduction>1</mechanicalReduction>
    </actuator>
  </transmission>
  <transmission name="LHipPitch_Transmission">
    <type>transmission_interface/SimpleTransmission</type>
    <joint name="LHipPitch">
      <hardwareInterface>EffortJointInterface</hardwareInterface>
    </joint>
    <actuator name="LHipPitch_Motor">
      <hardwareInterface>EffortJointInterface</hardwareInterface>
      <mechanicalReduction>1</mechanicalReduction>
    </actuator>
  </transmission>
  <transmission name="LKneePitch_Transmission">
    <type>transmission_interface/SimpleTransmission</type>
    <joint name="LKneePitch">
      <hardwareInterface>EffortJointInterface</hardwareInterface>
    </joint>
    <actuator name="LKneePitch_Motor">
      <hardwareInterface>EffortJointInterface</hardwareInterface>
      <mechanicalReduction>1</mechanicalReduction>
    </actuator>
  </transmission>
  <transmission name="LAnklePitch_Transmission">
    <type>transmission_interface/SimpleTransmission</type>
    <joint name="LAnklePitch">
      <hardwareInterface>EffortJointInterface</hardwareInterface>
    </joint>
    <actuator name="LAnklePitch_Motor">
      <hardwareInterface>EffortJointInterface</hardwareInterface>
      <mechanicalReduction>1</mechanicalReduction>
    </actuator>
  </transmission>
  <transmission name="LAnkleRoll_Transmission">
    <type>transmission_interface/SimpleTransmission</type>
    <joint name="LAnkleRoll">
      <hardwareInterface>EffortJointInterface</hardwareInterface>
    </joint>
    <actuator name="LAnkleRoll_Motor">
      <hardwareInterface>EffortJointInterface</hardwareInterface>
      <mechanicalReduction>1</mechanicalReduction>
    </actuator>
  </transmission>
  <transmission name="RHipYaw_Transmission">
    <type>transmission_interface/SimpleTransmission</type>
    <joint name="RHipYaw">
      <hardwareInterface>EffortJointInterface</hardwareInterface>
    </joint>
    <actuator name="RHipYaw_Motor">
      <hardwareInterface>EffortJointInterface</hardwareInterface>
      <mechanicalReduction>1</mechanicalReduction>
    </actuator>
  </transmission>
  <transmission name="RHipRoll_Transmission">
    <type>transmission_interface/SimpleTransmission</type>
    <joint name="RHipRoll">
      <hardwareInterface>EffortJointInterface</hardwareInterface>
    </joint>
    <actuator name="RHipRoll_Motor">
      <hardwareInterface>EffortJointInterface</hardwareInterface>
      <mechanicalReduction>1</mechanicalReduction>
    </actuator>
  </transmission>
  <transmission name="RHipPitch_Transmission">
    <type>transmission_interface/SimpleTransmission</type>
    <joint name="RHipPitch">
      <hardwareInterface>EffortJointInterface</hardwareInterface>
    </joint>
    <actuator name="RHipPitch_Motor">
      <hardwareInterface>EffortJointInterface</hardwareInterface>
      <mechanicalReduction>1</mechanicalReduction>
    </actuator>
  </transmission>
  <transmission name="RKneePitch_Transmission">
    <type>transmission_interface/SimpleTransmission</type>
    <joint name="RKneePitch">
      <hardwareInterface>EffortJointInterface</hardwareInterface>
    </joint>
    <actuator name="RKneePitch_Motor">
      <hardwareInterface>EffortJointInterface</hardwareInterface>
      <mechanicalReduction>1</mechanicalReduction>
    </actuator>
  </transmission>
  <transmission name="RAnklePitch_Transmission">
    <type>transmission_interface/SimpleTransmission</type>
    <joint name="RAnklePitch">
      <hardwareInterface>EffortJointInterface</hardwareInterface>
    </joint>
    <actuator name="RAnklePitch_Motor">
      <hardwareInterface>EffortJointInterface</hardwareInterface>
      <mechanicalReduction>1</mechanicalReduction>
    </actuator>
  </transmission>
  <transmission name="RAnkleRoll_Transmission">
    <type>transmission_interface/SimpleTransmission</type>
    <joint name="RAnkleRoll">
      <hardwareInterface>EffortJointInterface</hardwareInterface>
    </joint>
    <actuator name="RAnkleRoll_Motor">
      <hardwareInterface>EffortJointInterface</hardwareInterface>
      <mechanicalReduction>1</mechanicalReduction>
    </actuator>
  </transmission>
  <gazebo>
    <plugin filename="libgazebo_ros_control.so" name="gazebo_ros_control">
      <robotNamespace>/hros5</robotNamespace>
      <robotSimType>gazebo_ros_control/DefaultRobotHWSim</robotSimType>
    </plugin>
  </gazebo>
  <link name="base_link"/>
  <joint name="fixed-base" type="fixed">
    <parent link="base_link"/>
    <child link="torso"/>
  </joint>
  <link name="torso">
    <visual>
      <origin rpy="0 0 0" xyz="0 0 0"/>
      <geometry>
        <mesh filename="package://hros5_description/meshes/endoskeleton/visual/torso.dae" scale="0.1 0.1 0.1"/>
      </geometry>
    </visual>
    <collision>
      <origin rpy="0 0 0" xyz="0 0 0"/>
      <geometry>
        <mesh filename="package://hros5_description/meshes/endoskeleton/collision/torso.stl" scale="0.1 0.1 0.1"/>
      </geometry>
    </collision>
  </link>
  <joint name="HeadYaw" type="revolute">
    <parent link="torso"/>
    <child link="LowerHead"/>
    <!-- <origin xyz="-0.00661 -0.014699 0.16054" rpy="0 0 0"/> -->
    <origin rpy="0 0 0" xyz="0.0035 0 0.1115"/>
    <axis xyz="0 0 1"/>
    <limit effort="2.5" lower="-1.22173048" upper="1.22173048" velocity="5.759586525"/>
  </joint>
  <link name="LowerHead">
    <visual>
      <origin rpy="0 0 0" xyz="-0.03 0 0.033"/>
      <geometry>
        <mesh filename="package://hros5_description/meshes/endoskeleton/visual/LowerHead.dae" scale="0.1 0.1 0.1"/>
      </geometry>
    </visual>
    <collision>
      <origin rpy="0 0 0" xyz="-0.03 0 0.033"/>
      <geometry>
        <mesh filename="package://hros5_description/meshes/endoskeleton/collision/LowerHead.stl" scale="0.1 0.1 0.1"/>
      </geometry>
    </collision>
  </link>
  <joint name="HeadPitch" type="revolute">
    <parent link="LowerHead"/>
    <child link="UpperHeadBase"/>
    <origin rpy="0 0 0" xyz="-0.01 0 0.049"/>
    <axis xyz="0 1 0"/>
    <limit effort="2.5" lower="-0.25" upper="0.4" velocity="5.759586525"/>
  </joint>
  <link name="UpperHeadBase">
    <visual>
      <!-- <origin xyz="-0.01175 -0.0025 0.033" rpy="0 0 0"/> -->
      <origin rpy="0 0 0" xyz="0.0075 -0.0045 0.0275"/>
      <geometry>
        <mesh filename="package://hros5_description/meshes/endoskeleton/visual/UpperHeadBase.dae" scale="0.1 0.1 0.1"/>
      </geometry>
    </visual>
    <collision>
      <origin rpy="0 0 0" xyz="0.0075 -0.0045 0.0275"/>
      <geometry>
        <mesh filename="package://hros5_description/meshes/endoskeleton/collision/UpperHeadBase.stl" scale="0.1 0.1 0.1"/>
      </geometry>
    </collision>
  </link>
  <joint name="HeadPitchDummy" type="continuous">
    <parent link="UpperHeadBase"/>
    <child link="UpperHeadMotor"/>
    <origin rpy="0 0 0" xyz="-0.00225 0 0.046"/>
    <axis xyz="0 1 0"/>
    <mimic joint="HeadPitch" multiplier="-1.0"/>
  </joint>
  <link name="UpperHeadMotor">
    <visual>
      <origin rpy="0 0 0" xyz="-0.03 0 0.00075"/>
      <geometry>
        <mesh filename="package://hros5_description/meshes/endoskeleton/visual/UpperHeadMotor.dae" scale="0.1 0.1 0.1"/>
      </geometry>
    </visual>
    <collision>
      <origin rpy="0 0 0" xyz="-0.03 0 0.00075"/>
      <geometry>
        <mesh filename="package://hros5_description/meshes/endoskeleton/collision/UpperHeadMotor.stl" scale="0.1 0.1 0.1"/>
      </geometry>
    </collision>
  </link>
  <joint name="HeadPitchDummy2" type="continuous">
    <parent link="LowerHead"/>
    <child link="UpperHeadBack"/>
    <!-- <origin xyz="-0.04 0 -0.074" rpy="0 0 0"/> -->
    <origin rpy="0 0 0" xyz="-0.0525 0 0.021"/>
    <axis xyz="0 1 0"/>
    <mimic joint="HeadPitch" multiplier="0.65"/>
  </joint>
  <link name="UpperHeadBack">
    <visual>
      <origin rpy="0 0 0" xyz="0.001 0 0.0375"/>
      <geometry>
        <mesh filename="package://hros5_description/meshes/endoskeleton/visual/UpperHeadBack.dae" scale="0.1 0.1 0.1"/>
      </geometry>
    </visual>
    <collision>
      <origin rpy="0 0 0" xyz="0.001 0 0.0375"/>
      <geometry>
        <mesh filename="package://hros5_description/meshes/endoskeleton/collision/UpperHeadBack.stl" scale="0.1 0.1 0.1"/>
      </geometry>
    </collision>
  </link>
  <joint name="gaze_joint" type="fixed">
    <parent link="UpperHeadBase"/>
    <child link="gaze"/>
    <origin rpy="0 0 0" xyz="0 0 0"/>
  </joint>
  <link name="gaze"/>
  <joint name="LShoulderPitch" type="revolute">
    <parent link="torso"/>
    <child link="LShoulder"/>
    <!-- <origin xyz="-0.001114 0.079433 0.072086" rpy="0 0 0"/> -->
    <origin rpy="0 0 0" xyz="0.003 0.0675 0.084"/>
    <axis xyz="0 1 0"/>
    <limit effort="6.0" lower="-3.14159265" upper="3.14159265" velocity="6.597344565"/>
  </joint>
  <link name="LShoulder">
    <visual>
      <origin rpy="0 0 0" xyz="0 0.0122 -0.0125"/>
      <geometry>
        <mesh filename="package://hros5_description/meshes/endoskeleton/visual/LShoulder.dae" scale="0.1 0.1 0.1"/>
      </geometry>
    </visual>
    <collision>
      <origin rpy="0 0 0" xyz="0 0.0122 -0.0125"/>
      <geometry>
        <mesh filename="package://hros5_description/meshes/endoskeleton/collision/LShoulder.stl" scale="0.1 0.1 0.1"/>
      </geometry>
    </collision>
  </link>
  <link name="LUpperArm">
    <visual>
      <origin rpy="0 0 0" xyz="0 -0.00025 -0.0395"/>
      <geometry>
        <mesh filename="package://hros5_description/meshes/endoskeleton/visual/LUpperArm.dae" scale="0.1 0.1 0.1"/>
      </geometry>
    </visual>
    <collision>
      <origin rpy="0 0 0" xyz="0 -0.00025 -0.0395"/>
      <geometry>
        <mesh filename="package://hros5_description/meshes/endoskeleton/collision/LUpperArm.stl" scale="0.1 0.1 0.1"/>
      </geometry>
    </collision>
  </link>
  <joint name="LElbowPitch" type="revolute">
    <parent link="LUpperArm"/>
    <child link="LLowerArm"/>
    <origin rpy="0 0 0" xyz="0.03 -0.0015 -0.085"/>
    <axis xyz="0 1 0"/>
    <limit effort="6.0" lower="-1.22173048" upper="1.65806279" velocity="6.597344565"/>
  </joint>
  <link name="LLowerArm">
    <visual>
      <origin rpy="0 0 0" xyz="-0.0023 0 -0.0408"/>
      <geometry>
        <mesh filename="package://hros5_description/meshes/endoskeleton/visual/LLowerArm.dae" scale="0.1 0.1 0.1"/>
      </geometry>
    </visual>
    <collision>
      <origin rpy="0 0 0" xyz="-0.0023 0 -0.0408"/>
      <geometry>
        <mesh filename="package://hros5_description/meshes/endoskeleton/collision/LLowerArm.stl" scale="0.1 0.1 0.1"/>
      </geometry>
    </collision>
  </link>
  <joint name="RShoulderPitch" type="revolute">
    <parent link="torso"/>
    <child link="RShoulder"/>
    <!-- <origin xyz="-0.001114 0.079433 0.072086" rpy="0 0 0"/> -->
    <origin rpy="0 0 0" xyz="0.003 -0.0675 0.084"/>
    <axis xyz="0 1 0"/>
    <limit effort="6.0" lower="-3.14159265" upper="3.14159265" velocity="6.597344565"/>
  </joint>
  <link name="RShoulder">
    <visual>
      <origin rpy="0 0 0" xyz="0 -0.0122 -0.0125"/>
      <geometry>
        <mesh filename="package://hros5_description/meshes/endoskeleton/visual/RShoulder.dae" scale="0.1 0.1 0.1"/>
      </geometry>
    </visual>
    <collision>
      <origin rpy="0 0 0" xyz="0 -0.0122 -0.0125"/>
      <geometry>
        <mesh filename="package://hros5_description/meshes/endoskeleton/collision/RShoulder.stl" scale="0.1 0.1 0.1"/>
      </geometry>
    </collision>
  </link>
  <link name="RUpperArm">
    <visual>
      <origin rpy="0 0 0" xyz="0 0.00025 -0.0395"/>
      <geometry>
        <mesh filename="package://hros5_description/meshes/endoskeleton/visual/RUpperArm.dae" scale="0.1 0.1 0.1"/>
      </geometry>
    </visual>
    <collision>
      <origin rpy="0 0 0" xyz="0 0.00025 -0.0395"/>
      <geometry>
        <mesh filename="package://hros5_description/meshes/endoskeleton/collision/RUpperArm.stl" scale="0.1 0.1 0.1"/>
      </geometry>
    </collision>
  </link>
  <joint name="RElbowPitch" type="revolute">
    <parent link="RUpperArm"/>
    <child link="RLowerArm"/>
    <origin rpy="0 0 0" xyz="0.03 0.0015 -0.085"/>
    <axis xyz="0 1 0"/>
    <limit effort="6.0" lower="-1.65806279" upper="1.22173048" velocity="6.597344565"/>
  </joint>
  <link name="RLowerArm">
    <visual>
      <origin rpy="0 0 0" xyz="-0.0023 0 -0.0408"/>
      <geometry>
        <mesh filename="package://hros5_description/meshes/endoskeleton/visual/RLowerArm.dae" scale="0.1 0.1 0.1"/>
      </geometry>
    </visual>
    <collision>
      <origin rpy="0 0 0" xyz="-0.0023 0 -0.0408"/>
      <geometry>
        <mesh filename="package://hros5_description/meshes/endoskeleton/collision/RLowerArm.stl" scale="0.1 0.1 0.1"/>
      </geometry>
    </collision>
  </link>
  <joint name="LShoulderRoll" type="revolute">
    <parent link="LShoulder"/>
    <child link="LUpperArm"/>
    <origin rpy="0.174532925 0 0" xyz="0.002 0.03 -0.03"/>
    <axis xyz="1 0 0"/>
    <limit effort="6.0" lower="-2.35619449" upper="1.30899694" velocity="6.597344565"/>
  </joint>
  <joint name="RShoulderRoll" type="revolute">
    <parent link="RShoulder"/>
    <child link="RUpperArm"/>
    <origin rpy="-0.174532925 0 0" xyz="0.002 -0.03 -0.03"/>
    <axis xyz="1 0 0"/>
    <limit effort="6.0" lower="-1.30899694" upper="2.35619449" velocity="6.597344565"/>
  </joint>
  <joint name="l_wrist_joint" type="fixed">
    <parent link="LLowerArm"/>
    <child link="l_wrist"/>
    <origin rpy="0 0 0" xyz="0 0 -0.0425"/>
  </joint>
  <link name="l_wrist"/>
  <joint name="r_wrist_joint" type="fixed">
    <parent link="RLowerArm"/>
    <child link="r_wrist"/>
    <origin rpy="0 0 0" xyz="0 0 -0.0425"/>
  </joint>
  <link name="r_wrist"/>
  <joint name="LHipYaw" type="revolute">
    <parent link="torso"/>
    <child link="LHip"/>
    <!-- <origin xyz="-0.00145 0.048 -0.071931" rpy="0 0 0"/> -->
    <origin rpy="0 0 0" xyz="0.0175 0.048 -0.063"/>
    <axis xyz="0 0 1"/>
    <limit effort="8.4" lower="-0.523598776" upper="0.523598776" velocity="4.712388975"/>
  </joint>
  <link name="LHip">
    <visual>
      <origin rpy="0 0 0" xyz="-0.01605 0 -0.008931"/>
      <geometry>
        <mesh filename="package://hros5_description/meshes/endoskeleton/visual/LHip.dae" scale="0.1 0.1 0.1"/>
      </geometry>
    </visual>
    <collision>
      <origin rpy="0 0 0" xyz="-0.01605 0 -0.008931"/>
      <geometry>
        <mesh filename="package://hros5_description/meshes/endoskeleton/collision/LHip.stl" scale="0.1 0.1 0.1"/>
      </geometry>
    </collision>
  </link>
  <joint name="LHipRoll" type="revolute">
    <parent link="LHip"/>
    <child link="LHipMotors"/>
    <!-- <origin xyz="0.047519 0.048 -0.097025" rpy="0 0 0"/> 0.0033019-->
    <origin rpy="0 0 0" xyz="-0.0675 0 -0.034"/>
    <axis xyz="1 0 0"/>
    <limit effort="8.4" lower="-0.785398163" upper="0.785398163" velocity="4.712388975"/>
  </joint>
  <link name="LHipMotors">
    <visual>
      <origin rpy="0 0 0" xyz="0.077 -0.0052 -0.0041"/>
      <geometry>
        <mesh filename="package://hros5_description/meshes/endoskeleton/visual/LHipMotors.dae" scale="0.1 0.1 0.1"/>
      </geometry>
    </visual>
    <collision>
      <origin rpy="0 0 0" xyz="0.077 -0.0052 -0.0041"/>
      <geometry>
        <mesh filename="package://hros5_description/meshes/endoskeleton/collision/LHipMotors.stl" scale="0.1 0.1 0.1"/>
      </geometry>
    </collision>
  </link>
  <joint name="LHipPitch" type="revolute">
    <parent link="LHipMotors"/>
    <child link="LThigh"/>
    <origin rpy="0 0 0" xyz="0.0705 0 0"/>
    <axis xyz="0 1 0"/>
    <limit effort="8.4" lower="-1.57079633" upper="1.57079633" velocity="4.712388975"/>
  </joint>
  <link name="LThigh">
    <visual>
      <!-- <origin xyz="0.043764 0.038393 -0.188164" rpy="0 0 0"/> -->
      <origin rpy="0 0 0" xyz="0.001 -0.0095 -0.095"/>
      <geometry>
        <mesh filename="package://hros5_description/meshes/endoskeleton/visual/LThigh.dae" scale="0.1 0.1 0.1"/>
      </geometry>
    </visual>
    <collision>
      <origin rpy="0 0 0" xyz="0.001 -0.0095 -0.095"/>
      <geometry>
        <mesh filename="package://hros5_description/meshes/endoskeleton/collision/LThigh.stl" scale="0.1 0.1 0.1"/>
      </geometry>
    </collision>
  </link>
  <joint name="LKneePitch" type="revolute">
    <parent link="LThigh"/>
    <child link="LTibia"/>
    <origin rpy="0 0 0" xyz="0.0017 0 -0.127"/>
    <axis xyz="0 1 0"/>
    <limit effort="8.4" lower="-2.7925268" upper="2.7925268" velocity="4.712388975"/>
  </joint>
  <link name="LTibia">
    <visual>
      <!-- <origin xyz="0.041317 0.047709 -0.276974" rpy="0 0 0"/> -->
      <origin rpy="0 0 0" xyz="0.004 0 -0.059"/>
      <geometry>
        <mesh filename="package://hros5_description/meshes/endoskeleton/visual/LTibia.dae" scale="0.1 0.1 0.1"/>
      </geometry>
    </visual>
    <collision>
      <origin rpy="0 0 0" xyz="0.004 0 -0.059"/>
      <geometry>
        <mesh filename="package://hros5_description/meshes/endoskeleton/collision/LTibia.stl" scale="0.1 0.1 0.1"/>
      </geometry>
    </collision>
  </link>
  <joint name="LAnklePitch" type="revolute">
    <parent link="LTibia"/>
    <child link="LAnkle"/>
    <origin rpy="0 0 0" xyz="-0.002 0 -0.125"/>
    <!-- <origin xyz="0.024303 0.052837 -0.336141" rpy="0 0 0"/> -->
    <axis xyz="0 1 0"/>
    <limit effort="8.4" lower="-1.57079633" upper="1.57079633" velocity="4.712388975"/>
  </joint>
  <link name="LAnkle">
    <visual>
      <origin rpy="0 0 0" xyz="0.00625 0.00525 0.0042"/>
      <geometry>
        <mesh filename="package://hros5_description/meshes/endoskeleton/visual/LAnkle.dae" scale="0.1 0.1 0.1"/>
      </geometry>
    </visual>
    <collision>
      <origin rpy="0 0 0" xyz="0.00625 0.00525 0.0042"/>
      <geometry>
        <mesh filename="package://hros5_description/meshes/endoskeleton/collision/LAnkle.stl" scale="0.1 0.1 0.1"/>
      </geometry>
    </collision>
  </link>
  <joint name="LAnkleRoll" type="revolute">
    <parent link="LAnkle"/>
    <child link="LFoot"/>
    <origin rpy="0 0 0" xyz="-0.07 0 0"/>
    <axis xyz="1 0 0"/>
    <limit effort="8.4" lower="-0.785398163" upper="0.785398163" velocity="4.712388975"/>
  </joint>
  <link name="LFoot">
    <visual>
      <origin rpy="0 0 0" xyz="0.0565 0.007 -0.031"/>
      <geometry>
        <mesh filename="package://hros5_description/meshes/endoskeleton/visual/LFoot.dae" scale="0.1 0.1 0.1"/>
      </geometry>
    </visual>
    <collision>
      <origin rpy="0 0 0" xyz="0.0565 0.007 -0.031"/>
      <geometry>
        <mesh filename="package://hros5_description/meshes/endoskeleton/collision/LFoot.stl" scale="0.1 0.1 0.1"/>
      </geometry>
    </collision>
  </link>
  <joint name="RHipYaw" type="revolute">
    <parent link="torso"/>
    <child link="RHip"/>
    <!-- <origin xyz="-0.00145 0.048 -0.071931" rpy="0 0 0"/> -->
    <origin rpy="0 0 0" xyz="0.0175 -0.048 -0.063"/>
    <axis xyz="0 0 1"/>
    <limit effort="8.4" lower="-0.523598776" upper="0.523598776" velocity="4.712388975"/>
  </joint>
  <link name="RHip">
    <visual>
      <origin rpy="0 0 0" xyz="-0.01605 0 -0.008931"/>
      <geometry>
        <mesh filename="package://hros5_description/meshes/endoskeleton/visual/RHip.dae" scale="0.1 0.1 0.1"/>
      </geometry>
    </visual>
    <collision>
      <origin rpy="0 0 0" xyz="-0.01605 0 -0.008931"/>
      <geometry>
        <mesh filename="package://hros5_description/meshes/endoskeleton/collision/RHip.stl" scale="0.1 0.1 0.1"/>
      </geometry>
    </collision>
  </link>
  <joint name="RHipRoll" type="revolute">
    <parent link="RHip"/>
    <child link="RHipMotors"/>
    <!-- <origin xyz="0.047519 0.048 -0.097025" rpy="0 0 0"/> 0.0033019-->
    <origin rpy="0 0 0" xyz="-0.0675 0 -0.034"/>
    <axis xyz="1 0 0"/>
    <limit effort="8.4" lower="-0.785398163" upper="0.785398163" velocity="4.712388975"/>
  </joint>
  <link name="RHipMotors">
    <visual>
      <origin rpy="0 0 0" xyz="0.077 -0.0052 -0.0041"/>
      <geometry>
        <mesh filename="package://hros5_description/meshes/endoskeleton/visual/RHipMotors.dae" scale="0.1 0.1 0.1"/>
      </geometry>
    </visual>
    <collision>
      <origin rpy="0 0 0" xyz="0.077 -0.0052 -0.0041"/>
      <geometry>
        <mesh filename="package://hros5_description/meshes/endoskeleton/collision/RHipMotors.stl" scale="0.1 0.1 0.1"/>
      </geometry>
    </collision>
  </link>
  <joint name="RHipPitch" type="revolute">
    <parent link="RHipMotors"/>
    <child link="RThigh"/>
    <origin rpy="0 0 0" xyz="0.0705 0 0"/>
    <axis xyz="0 1 0"/>
    <limit effort="8.4" lower="-1.57079633" upper="1.57079633" velocity="4.712388975"/>
  </joint>
  <link name="RThigh">
    <visual>
      <!-- <origin xyz="0.043764 0.038393 -0.188164" rpy="0 0 0"/> -->
      <origin rpy="0 0 0" xyz="0.001 -0.0095 -0.095"/>
      <geometry>
        <mesh filename="package://hros5_description/meshes/endoskeleton/visual/RThigh.dae" scale="0.1 0.1 0.1"/>
      </geometry>
    </visual>
    <collision>
      <origin rpy="0 0 0" xyz="0.001 -0.0095 -0.095"/>
      <geometry>
        <mesh filename="package://hros5_description/meshes/endoskeleton/collision/RThigh.stl" scale="0.1 0.1 0.1"/>
      </geometry>
    </collision>
  </link>
  <joint name="RKneePitch" type="revolute">
    <parent link="RThigh"/>
    <child link="RTibia"/>
    <origin rpy="0 0 0" xyz="0.0017 0 -0.127"/>
    <axis xyz="0 1 0"/>
    <limit effort="8.4" lower="-2.7925268" upper="2.7925268" velocity="4.712388975"/>
  </joint>
  <link name="RTibia">
    <visual>
      <!-- <origin xyz="0.041317 0.047709 -0.276974" rpy="0 0 0"/> -->
      <origin rpy="0 0 0" xyz="0.004 0 -0.059"/>
      <geometry>
        <mesh filename="package://hros5_description/meshes/endoskeleton/visual/RTibia.dae" scale="0.1 0.1 0.1"/>
      </geometry>
    </visual>
    <collision>
      <origin rpy="0 0 0" xyz="0.004 0 -0.059"/>
      <geometry>
        <mesh filename="package://hros5_description/meshes/endoskeleton/collision/RTibia.stl" scale="0.1 0.1 0.1"/>
      </geometry>
    </collision>
  </link>
  <joint name="RAnklePitch" type="revolute">
    <parent link="RTibia"/>
    <child link="RAnkle"/>
    <origin rpy="0 0 0" xyz="-0.002 0 -0.125"/>
    <!-- <origin xyz="0.024303 0.052837 -0.336141" rpy="0 0 0"/> -->
    <axis xyz="0 1 0"/>
    <limit effort="8.4" lower="-1.57079633" upper="1.57079633" velocity="4.712388975"/>
  </joint>
  <link name="RAnkle">
    <visual>
      <origin rpy="0 0 0" xyz="0.00625 0.00525 0.0042"/>
      <geometry>
        <mesh filename="package://hros5_description/meshes/endoskeleton/visual/RAnkle.dae" scale="0.1 0.1 0.1"/>
      </geometry>
    </visual>
    <collision>
      <origin rpy="0 0 0" xyz="0.00625 0.00525 0.0042"/>
      <geometry>
        <mesh filename="package://hros5_description/meshes/endoskeleton/collision/RAnkle.stl" scale="0.1 0.1 0.1"/>
      </geometry>
    </collision>
  </link>
  <joint name="RAnkleRoll" type="revolute">
    <parent link="RAnkle"/>
    <child link="RFoot"/>
    <origin rpy="0 0 0" xyz="-0.07 0 0"/>
    <axis xyz="1 0 0"/>
    <limit effort="8.4" lower="-0.785398163" upper="0.785398163" velocity="4.712388975"/>
  </joint>
  <link name="RFoot">
    <visual>
      <origin rpy="0 0 0" xyz="0.0565 -0.007 -0.031"/>
      <geometry>
        <mesh filename="package://hros5_description/meshes/endoskeleton/visual/RFoot.dae" scale="0.1 0.1 0.1"/>
      </geometry>
    </visual>
    <collision>
      <origin rpy="0 0 0" xyz="0.0565 -0.007 -0.031"/>
      <geometry>
        <mesh filename="package://hros5_description/meshes/endoskeleton/collision/RFoot.stl" scale="0.1 0.1 0.1"/>
      </geometry>
    </collision>
  </link>
  <joint name="l_ankle_joint" type="fixed">
    <parent link="LAnkle"/>
    <child link="l_ankle"/>
    <origin rpy="0 0 0" xyz="0 0 0"/>
  </joint>
  <link name="l_ankle"/>
  <joint name="r_ankle_joint" type="fixed">
    <parent link="RAnkle"/>
    <child link="r_ankle"/>
    <origin rpy="0 0 0" xyz="0 0 0"/>
  </joint>
  <link name="r_ankle"/>
  <joint name="l_sole_joint" type="fixed">
    <parent link="LFoot"/>
    <child link="l_sole"/>
    <origin rpy="0 0 0" xyz="0.0565 0.007 -0.04"/>
  </joint>
  <link name="l_sole"/>
  <joint name="r_sole_joint" type="fixed">
    <parent link="RFoot"/>
    <child link="r_sole"/>
    <origin rpy="0 0 0" xyz="0.0565 -0.007 -0.04"/>
  </joint>
  <link name="r_sole"/>
</robot>

